Workbook

Sheet Lead Logs
A1: Tên KH | B1: AE | C1: Ngày nhận | D1: Ngày resolve | E1: Status | F1: Loại Lead | G1: Loại Unqualified | H1: Ghi chú thêm
A2: Cao Lâm | B2: Phương Linh | C2: 19/04/2026 | E2: Đang liên hệ | F2: Việt Nam | H2: Lần 1 liên hệ: Khách hàng mới đăng ký nhưng chưa có thời gian test sản phẩm Đã liên hệ Zalo nhưng KH chưa phản hồi lại
A3: Nguyen Huu Hung | B3: Phương Linh | C3: 19/04/2026 | E3: Đang liên hệ | F3: Việt Nam | H3: Lần 1 liên hệ: Khách hàng đang bận Đã liên hệ Zalo nhưng KH chưa phản hồi lại
A4: nguyen van toan | B4: Phương Linh | C4: 19/04/2026 | E4: Đang liên hệ | F4: Việt Nam | H4: Lần 1 liên hệ: Khách hàng chưa phản hồi được nhiều thông tin Đã liên hệ Zalo nhưng KH chưa phản hồi lại
A5: Võ Khánh Tùng | B5: Phương Linh | C5: 19/04/2026 | E5: Đang liên hệ | F5: Việt Nam | H5: Lần 1 liên hệ: Khách hàng đang bận Đã liên hệ Zalo nhưng KH chưa phản hồi lại
A6: lưu văn tú | B6: Phương Linh | C6: 19/04/2026 | E6: Đang liên hệ | F6: Việt Nam | H6: Lần 1 liên hệ: Khách hàng đã trải nghiệm sản phẩm và có khó khăn khi thao tác Đã liên hệ Zalo nhưng KH chưa phản hồi lại
A7: Maika Dwi | B7: Phương Linh | C7: 19/04/2026 | E7: Mới | F7: Quốc Tế
A8: primebet 88 | B8: Phương Linh | C8: 19/04/2026 | E8: Mới | F8: Quốc Tế
A9: Cao Văn Minh | B9: Phương Linh | C9: 19/04/2026 | E9: Đang liên hệ | F9: Việt Nam | H9: Lần 1 liên hệ: Khách hàng đang dùng SĐT của vợ để đăng ký nên chưa lấy được thông tin Đã liên hệ Zalo nhưng KH k accept zalo để trao đổi ( chặn người lạ )
A10: thanee keawsombat | B10: Phương Linh | C10: 19/04/2026 | E10: Mới | F10: Quốc Tế
A11: Chao Dara | B11: Phương Linh | C11: 19/04/2026 | E11: Mới | F11: Quốc Tế
A12: 刘散散 | B12: Phương Linh | C12: 19/04/2026 | E12: Mới | F12: Quốc Tế
A13: NL LEICA | B13: Phương Linh | C13: 19/04/2026 | E13: Đang liên hệ | F13: Việt Nam | H13: Lần 1 liên hệ: Khách có bắt máy nhưng k có âm thanh hay hồi âm với AE Đã liên hệ Zalo nhưng KH chưa phản hồi lại
A14: tuấn | B14: Phương Linh | C14: 19/04/2026 | E14: Đang liên hệ | F14: Việt Nam | H14: Lần 1 liên hệ: KH không nghe máy Đã liên hệ Zalo nhưng KH chưa phản hồi lại
A15: Nguyên Tuấn | B15: Phương Linh | C15: 19/04/2026 | E15: Unqualified | F15: Việt Nam | G15: Rejected | H15: KH k có nhu cầu
A16: Ngo David | B16: Phương Linh | C16: 19/04/2026 | E16: Unqualified | F16: Việt Nam | G16: Timing | H16: KH hiện chưa có nhu cầu sẽ tự tìm hiểu sau
A17: Sh2aWa | B17: Phương Linh | C17: 19/04/2026 | E17: Mới | F17: Quốc Tế
A18: TRAN LINH | B18: Phương Linh | C18: 19/04/2026 | E18: Unqualified | F18: Việt Nam | G18: Rejected | H18: KH k có nhu cầu
A19: Tuyên | B19: Phương Linh | C19: 19/04/2026 | E19: Đang liên hệ | F19: Việt Nam | H19: Lần 1 liên hệ: KH không nghe máy Đã liên hệ Zalo nhưng KH chưa phản hồi lại
A20: lucky wind | B20: Phương Linh | C20: 19/04/2026 | D20: 19/04/2026 | E20: Qualified | F20: Việt Nam | H20: KH là Agency, triển khai cho khách + dịch vụ cho khách thuê tài khoản quảng cáo KH có 2 cái BM 2500 full tài khoản, ngoài ra các BM nhỏ thì cũng nhiều nhưng ko cho thuê trên đó. Bth KH triển khai trên nhiều nền tảng, nên ngân sách cho 30-40 đối tác trung bình mỗi nền tảng tầm 1,5-2 tỷ. Nhưng đợt này KH tính là thêm dịch vụ cho thuê, thì chắc ngân sách sẽ lớn hơn
A21: Đăng Lê | B21: Phương Linh | C21: 19/04/2026 | E21: Đang liên hệ | F21: Việt Nam | H21: Lần 1 liên hệ: KH không nghe máy Đã liên hệ Zalo nhưng KH chưa phản hồi lại
A22: nguyenvanuy | B22: Phương Linh | C22: 19/04/2026 | E22: Đang liên hệ | F22: Việt Nam | H22: Lần 1 liên hệ: KH không nghe máy Đã liên hệ Zalo nhưng KH chưa phản hồi lại
A23: Nguyễn Toàn | B23: Phương Linh | C23: 19/04/2026 | E23: Đang liên hệ | F23: Việt Nam | H23: Lần 1 liên hệ: KH nghe máy nhưng âm thanh kém KH k nghe thấy Đã liên hệ Zalo nhưng KH chưa phản hồi lại
A24: hoang van hieu | B24: Phương Linh | C24: 19/04/2026 | E24: Đang liên hệ | F24: Việt Nam | H24: Lần 1 liên hệ: KH nghe máy nhưng âm thanh kém KH k nghe thấy Đã liên hệ Zalo nhưng KH chưa phản hồi lại
A25: quang | B25: Phương Linh | C25: 19/04/2026 | E25: Đang liên hệ | F25: Việt Nam | H25: Lần 1 liên hệ: KH k nghe máy Đã liên hệ Zalo nhưng KH chặn người lạ
A26: Ngọc Minh | B26: Phương Linh | C26: 19/04/2026 | E26: Đang liên hệ | F26: Việt Nam | H26: Lần 1 liên hệ: KH không nghe máy Đã liên hệ Zalo nhưng KH chưa phản hồi lại
A27: Tiến bằng Nguyễn | B27: Phương Linh | C27: 19/04/2026 | E27: Đang liên hệ | F27: Việt Nam | H27: Lần 1 liên hệ: KH có nghe máy nhưng k nghe rõ được lời của KH Đã liên hệ Zalo nhưng KH chưa phản hồi lại
A28: Hoàn trần | B28: Phương Linh | C28: 19/04/2026 | E28: Đang liên hệ | F28: Việt Nam | H28: Lần 1 liên hệ: KH không nghe máy Đã liên hệ Zalo nhưng KH chưa phản hồi lại
A29: Đỗ Công | B29: Phương Linh | C29: 19/04/2026 | E29: Đang nuôi dưỡng | F29: Việt Nam | H29: Lần 1 liên hệ: Khách hàng tự chạy quảng cáo. Ngân sách chạy 1-2tr/1 tháng. Khách hàng chưa lưu ý tính năng nào, quan tâm giá cả
A30: trung nguyen | B30: Phương Linh | C30: 19/04/2026 | E30: Mới | F30: Việt Nam
A31: Thành Trương | B31: Phương Linh | C31: 19/04/2026 | E31: Đang liên hệ | F31: Việt Nam | H31: Lần 1 liên hệ: KH không nghe máy Đã liên hệ Zalo nhưng KH chưa phản hồi lại
A32: Nhung L U Z Y | B32: Phương Linh | C32: 19/04/2026 | E32: Unqualified | F32: Việt Nam | H32: Lần 1 liên hệ: KH đang chưa hình dung được sản phẩm vì có thể là người khác đăng ký Đã liên hệ Zalo nhưng KH chưa phản hồi lại
A33: Nguyen trung hieu | B33: Phương Linh | C33: 19/04/2026 | E33: Đang liên hệ | F33: Việt Nam | H33: Lần 1 liên hệ: Khách hàng đang bận Đã liên hệ Zalo nhưng KH chưa phản hồi lại
A34: YuuAcc | B34: Phương Linh | C34: 19/04/2026 | E34: Mới | F34: Quốc Tế
A35: Chung Hà | B35: Phương Linh | C35: 19/04/2026 | E35: Đang liên hệ | F35: Việt Nam | H35: Lần 1 liên hệ: Ngoài giờ làm việc nên KH hẹn mai Đã tìm Zalo nhưng SĐT không hiển thị Zalo của KH
A36: lê anh | B36: Phương Linh | C36: 19/04/2026 | E36: Đang liên hệ | F36: Việt Nam | H36: Lần 1 liên hệ: KH không nghe máy Đã tìm Zalo nhưng KH chặn người lạ
A37: Cường Trương Thế | B37: Phương Linh | C37: 19/04/2026 | E37: Đang liên hệ | F37: Việt Nam | H37: Lần 1 liên hệ: KH có nghe máy và tự chạy QC Đã liên hệ Zalo nhưng KH chưa phản hồi lại
A38: roeunnarong | B38: Phương Linh | C38: 19/04/2026 | E38: Mới | F38: Quốc Tế
A39: Dinh Trong Nguyen | B39: Phương Linh | C39: 19/04/2026 | E39: Mới | F39: Việt Nam
A40: NGUYEN CONG DIEN | B40: Phương Linh | C40: 19/04/2026 | E40: Mới | F40: Việt Nam
...

Sheet Daily
A1: Ngày | B1: AE Hồng Nhung | G1: AE Kim Huệ | L1: AE Phương Linh
B2: Thêm | C2: Xử lý | D2: Tồn cuối ngày | E2: Tỷ lệ xử lý trong ngày | F2: Tỷ lệ xử lý trên tổng | G2: Thêm | H2: Xử lý | I2: Tồn cuối ngày | J2: Tỷ lệ xử lý trong ngày | K2: Tỷ lệ xử lý trên tổng | L2: Thêm | M2: Xử lý | N2: Tồn cuối ngày | O2: Tỷ lệ xử lý trong ngày | P2: Tỷ lệ xử lý trên tổng
A3: 46131 | D3: 0 | I3: 0 | N3: 0
A4: 46132 | B4: =COUNTIFS('Lead Logs'!B:B,"Hồng Nhung",'Lead Logs'!C:C,A4) | C4: =COUNTIFS('Lead Logs'!B:B,"Hồng Nhung",'Lead Logs'!D:D,A4,'Lead Logs'!E:E,"Qualified")+COUNTIFS('Lead Logs'!B:B,"Hồng Nhung",'Lead Logs'!D:D,A4,'Lead Logs'!E:E,"Unqualified") | D4: =D3+B4-C4 | E4: =IFERROR(C4/B4,"-") | F4: =IFERROR(C4/(B4+D3),"-") | G4: =COUNTIFS(#REF!,"Kim Huệ",#REF!,A4) | H4: =COUNTIFS(#REF!,"Kim Huệ",#REF!,A4,#REF!,"Qualified")+COUNTIFS(#REF!,"Kim Huệ",#REF!,A4,#REF!,"Unqualified") | I4: =I3+G4-H4 | J4: =IFERROR(H4/G4,"-") | K4: =IFERROR(H4/(G4+I3),"-") | L4: =COUNTIFS(#REF!,"Phương Linh",#REF!,A4) | M4: =COUNTIFS(#REF!,"Phương Linh",#REF!,A4,#REF!,"Qualified")+COUNTIFS(#REF!,"Phương Linh",#REF!,A4,#REF!,"Unqualified") | N4: =N3+L4-M4 | O4: =IFERROR(M4/L4,"-") | P4: =IFERROR(M4/(L4+N3),"-")
A5: 46133 | B5: =COUNTIFS('Lead Logs'!B:B,"Hồng Nhung",'Lead Logs'!C:C,A5) | C5: =COUNTIFS('Lead Logs'!B:B,"Hồng Nhung",'Lead Logs'!D:D,A5,'Lead Logs'!E:E,"Qualified")+COUNTIFS('Lead Logs'!B:B,"Hồng Nhung",'Lead Logs'!D:D,A5,'Lead Logs'!E:E,"Unqualified") | D5: =D4+B5-C5 | E5: =IFERROR(C5/B5,"-") | F5: =IFERROR(C5/(B5+D4),"-") | G5: =COUNTIFS(#REF!,"Kim Huệ",#REF!,A5) | H5: =COUNTIFS(#REF!,"Kim Huệ",#REF!,A5,#REF!,"Qualified")+COUNTIFS(#REF!,"Kim Huệ",#REF!,A5,#REF!,"Unqualified") | I5: =I4+G5-H5 | J5: =IFERROR(H5/G5,"-") | K5: =IFERROR(H5/(G5+I4),"-") | L5: =COUNTIFS(#REF!,"Phương Linh",#REF!,A5) | M5: =COUNTIFS(#REF!,"Phương Linh",#REF!,A5,#REF!,"Qualified")+COUNTIFS(#REF!,"Phương Linh",#REF!,A5,#REF!,"Unqualified") | N5: =N4+L5-M5 | O5: =IFERROR(M5/L5,"-") | P5: =IFERROR(M5/(L5+N4),"-")
A6: 46134 | B6: =COUNTIFS('Lead Logs'!B:B,"Hồng Nhung",'Lead Logs'!C:C,A6) | C6: =COUNTIFS('Lead Logs'!B:B,"Hồng Nhung",'Lead Logs'!D:D,A6,'Lead Logs'!E:E,"Qualified")+COUNTIFS('Lead Logs'!B:B,"Hồng Nhung",'Lead Logs'!D:D,A6,'Lead Logs'!E:E,"Unqualified") | D6: =D5+B6-C6 | E6: =IFERROR(C6/B6,"-") | F6: =IFERROR(C6/(B6+D5),"-") | G6: =COUNTIFS(#REF!,"Kim Huệ",#REF!,A6) | H6: =COUNTIFS(#REF!,"Kim Huệ",#REF!,A6,#REF!,"Qualified")+COUNTIFS(#REF!,"Kim Huệ",#REF!,A6,#REF!,"Unqualified") | I6: =I5+G6-H6 | J6: =IFERROR(H6/G6,"-") | K6: =IFERROR(H6/(G6+I5),"-") | L6: =COUNTIFS(#REF!,"Phương Linh",#REF!,A6) | M6: =COUNTIFS(#REF!,"Phương Linh",#REF!,A6,#REF!,"Qualified")+COUNTIFS(#REF!,"Phương Linh",#REF!,A6,#REF!,"Unqualified") | N6: =N5+L6-M6 | O6: =IFERROR(M6/L6,"-") | P6: =IFERROR(M6/(L6+N5),"-")
A7: 46135 | B7: =COUNTIFS('Lead Logs'!B:B,"Hồng Nhung",'Lead Logs'!C:C,A7) | C7: =COUNTIFS('Lead Logs'!B:B,"Hồng Nhung",'Lead Logs'!D:D,A7,'Lead Logs'!E:E,"Qualified")+COUNTIFS('Lead Logs'!B:B,"Hồng Nhung",'Lead Logs'!D:D,A7,'Lead Logs'!E:E,"Unqualified") | D7: =D6+B7-C7 | E7: =IFERROR(C7/B7,"-") | F7: =IFERROR(C7/(B7+D6),"-") | G7: =COUNTIFS(#REF!,"Kim Huệ",#REF!,A7) | H7: =COUNTIFS(#REF!,"Kim Huệ",#REF!,A7,#REF!,"Qualified")+COUNTIFS(#REF!,"Kim Huệ",#REF!,A7,#REF!,"Unqualified") | I7: =I6+G7-H7 | J7: =IFERROR(H7/G7,"-") | K7: =IFERROR(H7/(G7+I6),"-") | L7: =COUNTIFS(#REF!,"Phương Linh",#REF!,A7) | M7: =COUNTIFS(#REF!,"Phương Linh",#REF!,A7,#REF!,"Qualified")+COUNTIFS(#REF!,"Phương Linh",#REF!,A7,#REF!,"Unqualified") | N7: =N6+L7-M7 | O7: =IFERROR(M7/L7,"-") | P7: =IFERROR(M7/(L7+N6),"-")
A8: 46136 | B8: =COUNTIFS('Lead Logs'!B:B,"Hồng Nhung",'Lead Logs'!C:C,A8) | C8: =COUNTIFS('Lead Logs'!B:B,"Hồng Nhung",'Lead Logs'!D:D,A8,'Lead Logs'!E:E,"Qualified")+COUNTIFS('Lead Logs'!B:B,"Hồng Nhung",'Lead Logs'!D:D,A8,'Lead Logs'!E:E,"Unqualified") | D8: =D7+B8-C8 | E8: =IFERROR(C8/B8,"-") | F8: =IFERROR(C8/(B8+D7),"-") | G8: =COUNTIFS(#REF!,"Kim Huệ",#REF!,A8) | H8: =COUNTIFS(#REF!,"Kim Huệ",#REF!,A8,#REF!,"Qualified")+COUNTIFS(#REF!,"Kim Huệ",#REF!,A8,#REF!,"Unqualified") | I8: =I7+G8-H8 | J8: =IFERROR(H8/G8,"-") | K8: =IFERROR(H8/(G8+I7),"-") | L8: =COUNTIFS(#REF!,"Phương Linh",#REF!,A8) | M8: =COUNTIFS(#REF!,"Phương Linh",#REF!,A8,#REF!,"Qualified")+COUNTIFS(#REF!,"Phương Linh",#REF!,A8,#REF!,"Unqualified") | N8: =N7+L8-M8 | O8: =IFERROR(M8/L8,"-") | P8: =IFERROR(M8/(L8+N7),"-")
A9: 46137 | B9: =COUNTIFS('Lead Logs'!B:B,"Hồng Nhung",'Lead Logs'!C:C,A9) | C9: =COUNTIFS('Lead Logs'!B:B,"Hồng Nhung",'Lead Logs'!D:D,A9,'Lead Logs'!E:E,"Qualified")+COUNTIFS('Lead Logs'!B:B,"Hồng Nhung",'Lead Logs'!D:D,A9,'Lead Logs'!E:E,"Unqualified") | D9: =D8+B9-C9 | E9: =IFERROR(C9/B9,"-") | F9: =IFERROR(C9/(B9+D8),"-") | G9: =COUNTIFS(#REF!,"Kim Huệ",#REF!,A9) | H9: =COUNTIFS(#REF!,"Kim Huệ",#REF!,A9,#REF!,"Qualified")+COUNTIFS(#REF!,"Kim Huệ",#REF!,A9,#REF!,"Unqualified") | I9: =I8+G9-H9 | J9: =IFERROR(H9/G9,"-") | K9: =IFERROR(H9/(G9+I8),"-") | L9: =COUNTIFS(#REF!,"Phương Linh",#REF!,A9) | M9: =COUNTIFS(#REF!,"Phương Linh",#REF!,A9,#REF!,"Qualified")+COUNTIFS(#REF!,"Phương Linh",#REF!,A9,#REF!,"Unqualified") | N9: =N8+L9-M9 | O9: =IFERROR(M9/L9,"-") | P9: =IFERROR(M9/(L9+N8),"-")
A10: 46138 | B10: =COUNTIFS('Lead Logs'!B:B,"Hồng Nhung",'Lead Logs'!C:C,A10) | C10: =COUNTIFS('Lead Logs'!B:B,"Hồng Nhung",'Lead Logs'!D:D,A10,'Lead Logs'!E:E,"Qualified")+COUNTIFS('Lead Logs'!B:B,"Hồng Nhung",'Lead Logs'!D:D,A10,'Lead Logs'!E:E,"Unqualified") | D10: =D9+B10-C10 | E10: =IFERROR(C10/B10,"-") | F10: =IFERROR(C10/(B10+D9),"-") | G10: =COUNTIFS(#REF!,"Kim Huệ",#REF!,A10) | H10: =COUNTIFS(#REF!,"Kim Huệ",#REF!,A10,#REF!,"Qualified")+COUNTIFS(#REF!,"Kim Huệ",#REF!,A10,#REF!,"Unqualified") | I10: =I9+G10-H10 | J10: =IFERROR(H10/G10,"-") | K10: =IFERROR(H10/(G10+I9),"-") | L10: =COUNTIFS(#REF!,"Phương Linh",#REF!,A10) | M10: =COUNTIFS(#REF!,"Phương Linh",#REF!,A10,#REF!,"Qualified")+COUNTIFS(#REF!,"Phương Linh",#REF!,A10,#REF!,"Unqualified") | N10: =N9+L10-M10 | O10: =IFERROR(M10/L10,"-") | P10: =IFERROR(M10/(L10+N9),"-")
A11: 46139 | B11: =COUNTIFS('Lead Logs'!B:B,"Hồng Nhung",'Lead Logs'!C:C,A11) | C11: =COUNTIFS('Lead Logs'!B:B,"Hồng Nhung",'Lead Logs'!D:D,A11,'Lead Logs'!E:E,"Qualified")+COUNTIFS('Lead Logs'!B:B,"Hồng Nhung",'Lead Logs'!D:D,A11,'Lead Logs'!E:E,"Unqualified") | D11: =D10+B11-C11 | E11: =IFERROR(C11/B11,"-") | F11: =IFERROR(C11/(B11+D10),"-") | G11: =COUNTIFS(#REF!,"Kim Huệ",#REF!,A11) | H11: =COUNTIFS(#REF!,"Kim Huệ",#REF!,A11,#REF!,"Qualified")+COUNTIFS(#REF!,"Kim Huệ",#REF!,A11,#REF!,"Unqualified") | I11: =I10+G11-H11 | J11: =IFERROR(H11/G11,"-") | K11: =IFERROR(H11/(G11+I10),"-") | L11: =COUNTIFS(#REF!,"Phương Linh",#REF!,A11) | M11: =COUNTIFS(#REF!,"Phương Linh",#REF!,A11,#REF!,"Qualified")+COUNTIFS(#REF!,"Phương Linh",#REF!,A11,#REF!,"Unqualified") | N11: =N10+L11-M11 | O11: =IFERROR(M11/L11,"-") | P11: =IFERROR(M11/(L11+N10),"-")
A12: 46140 | B12: =COUNTIFS('Lead Logs'!B:B,"Hồng Nhung",'Lead Logs'!C:C,A12) | C12: =COUNTIFS('Lead Logs'!B:B,"Hồng Nhung",'Lead Logs'!D:D,A12,'Lead Logs'!E:E,"Qualified")+COUNTIFS('Lead Logs'!B:B,"Hồng Nhung",'Lead Logs'!D:D,A12,'Lead Logs'!E:E,"Unqualified") | D12: =D11+B12-C12 | E12: =IFERROR(C12/B12,"-") | F12: =IFERROR(C12/(B12+D11),"-") | G12: =COUNTIFS(#REF!,"Kim Huệ",#REF!,A12) | H12: =COUNTIFS(#REF!,"Kim Huệ",#REF!,A12,#REF!,"Qualified")+COUNTIFS(#REF!,"Kim Huệ",#REF!,A12,#REF!,"Unqualified") | I12: =I11+G12-H12 | J12: =IFERROR(H12/G12,"-") | K12: =IFERROR(H12/(G12+I11),"-") | L12: =COUNTIFS(#REF!,"Phương Linh",#REF!,A12) | M12: =COUNTIFS(#REF!,"Phương Linh",#REF!,A12,#REF!,"Qualified")+COUNTIFS(#REF!,"Phương Linh",#REF!,A12,#REF!,"Unqualified") | N12: =N11+L12-M12 | O12: =IFERROR(M12/L12,"-") | P12: =IFERROR(M12/(L12+N11),"-")
A13: 46141 | B13: =COUNTIFS('Lead Logs'!B:B,"Hồng Nhung",'Lead Logs'!C:C,A13) | C13: =COUNTIFS('Lead Logs'!B:B,"Hồng Nhung",'Lead Logs'!D:D,A13,'Lead Logs'!E:E,"Qualified")+COUNTIFS('Lead Logs'!B:B,"Hồng Nhung",'Lead Logs'!D:D,A13,'Lead Logs'!E:E,"Unqualified") | D13: =D12+B13-C13 | E13: =IFERROR(C13/B13,"-") | F13: =IFERROR(C13/(B13+D12),"-") | G13: =COUNTIFS(#REF!,"Kim Huệ",#REF!,A13) | H13: =COUNTIFS(#REF!,"Kim Huệ",#REF!,A13,#REF!,"Qualified")+COUNTIFS(#REF!,"Kim Huệ",#REF!,A13,#REF!,"Unqualified") | I13: =I12+G13-H13 | J13: =IFERROR(H13/G13,"-") | K13: =IFERROR(H13/(G13+I12),"-") | L13: =COUNTIFS(#REF!,"Phương Linh",#REF!,A13) | M13: =COUNTIFS(#REF!,"Phương Linh",#REF!,A13,#REF!,"Qualified")+COUNTIFS(#REF!,"Phương Linh",#REF!,A13,#REF!,"Unqualified") | N13: =N12+L13-M13 | O13: =IFERROR(M13/L13,"-") | P13: =IFERROR(M13/(L13+N12),"-")
A14: 46142 | B14: =COUNTIFS('Lead Logs'!B:B,"Hồng Nhung",'Lead Logs'!C:C,A14) | C14: =COUNTIFS('Lead Logs'!B:B,"Hồng Nhung",'Lead Logs'!D:D,A14,'Lead Logs'!E:E,"Qualified")+COUNTIFS('Lead Logs'!B:B,"Hồng Nhung",'Lead Logs'!D:D,A14,'Lead Logs'!E:E,"Unqualified") | D14: =D13+B14-C14 | E14: =IFERROR(C14/B14,"-") | F14: =IFERROR(C14/(B14+D13),"-") | G14: =COUNTIFS(#REF!,"Kim Huệ",#REF!,A14) | H14: =COUNTIFS(#REF!,"Kim Huệ",#REF!,A14,#REF!,"Qualified")+COUNTIFS(#REF!,"Kim Huệ",#REF!,A14,#REF!,"Unqualified") | I14: =I13+G14-H14 | J14: =IFERROR(H14/G14,"-") | K14: =IFERROR(H14/(G14+I13),"-") | L14: =COUNTIFS(#REF!,"Phương Linh",#REF!,A14) | M14: =COUNTIFS(#REF!,"Phương Linh",#REF!,A14,#REF!,"Qualified")+COUNTIFS(#REF!,"Phương Linh",#REF!,A14,#REF!,"Unqualified") | N14: =N13+L14-M14 | O14: =IFERROR(M14/L14,"-") | P14: =IFERROR(M14/(L14+N13),"-")
A15: 46143 | B15: =COUNTIFS('Lead Logs'!B:B,"Hồng Nhung",'Lead Logs'!C:C,A15) | C15: =COUNTIFS('Lead Logs'!B:B,"Hồng Nhung",'Lead Logs'!D:D,A15,'Lead Logs'!E:E,"Qualified")+COUNTIFS('Lead Logs'!B:B,"Hồng Nhung",'Lead Logs'!D:D,A15,'Lead Logs'!E:E,"Unqualified") | D15: =D14+B15-C15 | E15: =IFERROR(C15/B15,"-") | F15: =IFERROR(C15/(B15+D14),"-") | G15: =COUNTIFS(#REF!,"Kim Huệ",#REF!,A15) | H15: =COUNTIFS(#REF!,"Kim Huệ",#REF!,A15,#REF!,"Qualified")+COUNTIFS(#REF!,"Kim Huệ",#REF!,A15,#REF!,"Unqualified") | I15: =I14+G15-H15 | J15: =IFERROR(H15/G15,"-") | K15: =IFERROR(H15/(G15+I14),"-") | L15: =COUNTIFS(#REF!,"Phương Linh",#REF!,A15) | M15: =COUNTIFS(#REF!,"Phương Linh",#REF!,A15,#REF!,"Qualified")+COUNTIFS(#REF!,"Phương Linh",#REF!,A15,#REF!,"Unqualified") | N15: =N14+L15-M15 | O15: =IFERROR(M15/L15,"-") | P15: =IFERROR(M15/(L15+N14),"-")
... A44: 46172 | B44: =COUNTIFS('Lead Logs'!B:B,"Hồng Nhung",'Lead Logs'!C:C,A44) | C44: =COUNTIFS('Lead Logs'!B:B,"Hồng Nhung",'Lead Logs'!D:D,A44,'Lead Logs'!E:E,"Qualified")+COUNTIFS('Lead Logs'!B:B,"Hồng Nhung",'Lead Logs'!D:D,A44,'Lead Logs'!E:E,"Unqualified") | D44: =D43+B44-C44 | E44: =IFERROR(C44/B44,"-") | F44: =IFERROR(C44/(B44+D43),"-") | G44: =COUNTIFS(#REF!,"Kim Huệ",#REF!,A44) | H44: =COUNTIFS(#REF!,"Kim Huệ",#REF!,A44,#REF!,"Qualified")+COUNTIFS(#REF!,"Kim Huệ",#REF!,A44,#REF!,"Unqualified") | I44: =I43+G44-H44 | J44: =IFERROR(H44/G44,"-") | K44: =IFERROR(H44/(G44+I43),"-") | L44: =COUNTIFS(#REF!,"Phương Linh",#REF!,A44) | M44: =COUNTIFS(#REF!,"Phương Linh",#REF!,A44,#REF!,"Qualified")+COUNTIFS(#REF!,"Phương Linh",#REF!,A44,#REF!,"Unqualified") | N44: =N43+L44-M44 | O44: =IFERROR(M44/L44,"-") | P44: =IFERROR(M44/(L44+N43),"-")
